{
 "cells": [
  {
   "cell_type": "code",
   "execution_count": 1,
   "metadata": {},
   "outputs": [],
   "source": [
    "import nldi\n"
   ]
  },
  {
   "cell_type": "code",
   "execution_count": 2,
   "metadata": {},
   "outputs": [],
   "source": [
    "import sys\n",
    "sys.path.append(\"../tests\")\n",
    "import conftest\n"
   ]
  },
  {
   "cell_type": "code",
   "execution_count": 3,
   "metadata": {},
   "outputs": [
    {
     "ename": "Failed",
     "evalue": "Fixture \"global_config\" called directly. Fixtures are not meant to be called directly,\nbut are created automatically when test functions request them as parameters.\nSee https://docs.pytest.org/en/stable/explanation/fixtures.html for more information about fixtures, and\nhttps://docs.pytest.org/en/stable/deprecations.html#calling-fixtures-directly about how to update your code.",
     "output_type": "error",
     "traceback": [
      "\u001b[0;31m---------------------------------------------------------------------------\u001b[0m",
      "\u001b[0;31mFailed\u001b[0m                                    Traceback (most recent call last)",
      "Cell \u001b[0;32mIn[3], line 1\u001b[0m\n\u001b[0;32m----> 1\u001b[0m \u001b[43mconftest\u001b[49m\u001b[38;5;241;43m.\u001b[39;49m\u001b[43mglobal_config\u001b[49m\u001b[43m(\u001b[49m\u001b[43m)\u001b[49m\n",
      "File \u001b[0;32m~/nldi-py/.venv/lib/python3.12/site-packages/_pytest/fixtures.py:1168\u001b[0m, in \u001b[0;36mwrap_function_to_error_out_if_called_directly.<locals>.result\u001b[0;34m(*args, **kwargs)\u001b[0m\n\u001b[1;32m   1166\u001b[0m \u001b[38;5;129m@functools\u001b[39m\u001b[38;5;241m.\u001b[39mwraps(function)\n\u001b[1;32m   1167\u001b[0m \u001b[38;5;28;01mdef\u001b[39;00m \u001b[38;5;21mresult\u001b[39m(\u001b[38;5;241m*\u001b[39margs, \u001b[38;5;241m*\u001b[39m\u001b[38;5;241m*\u001b[39mkwargs):\n\u001b[0;32m-> 1168\u001b[0m     \u001b[43mfail\u001b[49m\u001b[43m(\u001b[49m\u001b[43mmessage\u001b[49m\u001b[43m,\u001b[49m\u001b[43m \u001b[49m\u001b[43mpytrace\u001b[49m\u001b[38;5;241;43m=\u001b[39;49m\u001b[38;5;28;43;01mFalse\u001b[39;49;00m\u001b[43m)\u001b[49m\n",
      "File \u001b[0;32m~/nldi-py/.venv/lib/python3.12/site-packages/_pytest/outcomes.py:178\u001b[0m, in \u001b[0;36mfail\u001b[0;34m(reason, pytrace)\u001b[0m\n\u001b[1;32m    165\u001b[0m \u001b[38;5;250m\u001b[39m\u001b[38;5;124;03m\"\"\"Explicitly fail an executing test with the given message.\u001b[39;00m\n\u001b[1;32m    166\u001b[0m \n\u001b[1;32m    167\u001b[0m \u001b[38;5;124;03m:param reason:\u001b[39;00m\n\u001b[0;32m   (...)\u001b[0m\n\u001b[1;32m    175\u001b[0m \u001b[38;5;124;03m    The exception that is raised.\u001b[39;00m\n\u001b[1;32m    176\u001b[0m \u001b[38;5;124;03m\"\"\"\u001b[39;00m\n\u001b[1;32m    177\u001b[0m __tracebackhide__ \u001b[38;5;241m=\u001b[39m \u001b[38;5;28;01mTrue\u001b[39;00m\n\u001b[0;32m--> 178\u001b[0m \u001b[38;5;28;01mraise\u001b[39;00m Failed(msg\u001b[38;5;241m=\u001b[39mreason, pytrace\u001b[38;5;241m=\u001b[39mpytrace)\n",
      "\u001b[0;31mFailed\u001b[0m: Fixture \"global_config\" called directly. Fixtures are not meant to be called directly,\nbut are created automatically when test functions request them as parameters.\nSee https://docs.pytest.org/en/stable/explanation/fixtures.html for more information about fixtures, and\nhttps://docs.pytest.org/en/stable/deprecations.html#calling-fixtures-directly about how to update your code."
     ]
    }
   ],
   "source": [
    "conftest.global_config()"
   ]
  },
  {
   "cell_type": "code",
   "execution_count": null,
   "metadata": {},
   "outputs": [],
   "source": []
  }
 ],
 "metadata": {
  "kernelspec": {
   "display_name": ".venv",
   "language": "python",
   "name": "python3"
  },
  "language_info": {
   "codemirror_mode": {
    "name": "ipython",
    "version": 3
   },
   "file_extension": ".py",
   "mimetype": "text/x-python",
   "name": "python",
   "nbconvert_exporter": "python",
   "pygments_lexer": "ipython3",
   "version": "3.12.4"
  }
 },
 "nbformat": 4,
 "nbformat_minor": 2
}
